{
 "cells": [
  {
   "cell_type": "markdown",
   "metadata": {
    "colab_type": "text",
    "id": "mk8OnE7A1Vsw"
   },
   "source": [
    "# DISCLAIMER\n",
    "\n",
    "\n",
    "\n",
    "---\n",
    "\n",
    "Esse documento ainda precisa passar por revisões e ser aprovado para que possa ser publicado e compartilhado.\n",
    "\n",
    "Esse documento ainda não representa a ideia final e está sujeito a mudanças.\n",
    "\n",
    "---\n",
    "\n"
   ]
  },
  {
   "cell_type": "markdown",
   "metadata": {
    "colab_type": "text",
    "id": "6d6kpgatqA30"
   },
   "source": [
    "# CAPÍTULO 11\n",
    "## EXCEÇÕES E ERROS\n",
    "Voltando as contas que criamos no capítulo 6, o que aconteceria ao tentar chamar o método   saca() \n",
    "com um valor fora do limite? O sistema mostraria uma mensagem de erro, mas quem chamou o método\n",
    " saca()  não saberá que isso aconteceu.\n",
    "Como avisar aquele que chamou o método de que ele não conseguiu fazer aquilo que deveria?\n",
    "Os métodos dizem qual o contrato que eles devem seguir. Se, ao tentar   sacar() , ele não consegue\n",
    "fazer o que deveria, ele precisa, ao menos, avisar ao usuário que o saque não foi feito.\n",
    "Veja no exemplo abaixo: estamos forçando uma  Conta  a ter um valor negativo, isto é, estar em um\n",
    "estado inconsistente de acordo com a nossa modelagem.\n",
    "\n",
    "    conta = Conta('123-4', 'João')\n",
    "    conta.deposita(100.0)\n",
    "    conta.saca(3000.0)\n",
    "    #o método saca funcionou?\n",
    "\n",
    "Em  sistemas  de  verdade,  é  muito  comum  que  quem  saiba  tratar  o  erro  é  aquele  que  chamou  o\n",
    "método e não a própria classe! Portanto, nada mais natural sinalizar que um erro ocorreu.\n",
    "A solução mais simples utilizada antigamente é a de marcar o retorno de um método como boolean e\n",
    "retornar  True , se tudo ocorreu da maneira planejada, ou  False , caso contrário:\n",
    "\n",
    "    if (valor > self.saldo + self.limite):\n",
    "        print(\"nao posso sacar fora do limite\")\n",
    "        return False\n",
    "    else:\n",
    "        self.saldo -= valor\n",
    "        return True\n",
    "\n",
    "Um novo exemplo de chamada do método acima:\n",
    "\n",
    "    conta = Conta('123-4', 'João')\n",
    "    conta.deposita(100.0)\n",
    "    conta.limite = 100.0\n",
    "    if(not conta.saca(3000.0)):\n",
    "        print(\"nao saquei\")\n",
    "\n",
    "Repare que tivemos de lembrar de testar o retorno do método, mas não somos obrigados a fazer isso.\n",
    "Esquecer de testar o retorno desse método teria consequências drásticas: a máquina de autoatendimento\n",
    "poderia vir a liberar a quantia desejada de dinheiro, mesmo se o sistema não tivesse conseguido efetuar o\n",
    "método  saca()  com sucesso, como no exemplo a seguir:\n",
    "\n",
    "    conta = Conta(\"123-4\", \"João\")\n",
    "    conta.deposita(100.0)\n",
    "    # ...\n",
    "    valor = 5000.0\n",
    "    conta.saca(valor) # vai retornar False, mas ninguém verifica\n",
    "    caixa_eletronico.emite(valor)\n",
    "\n",
    "Mesmo  invocando  o  método  e  tratando  o  retorno  de  maneira  correta,  o  que  faríamos  se  fosse\n",
    "necessário sinalizar quando o usuário passou um valor negativo como valor. Uma solução seria alterar o\n",
    "retorno de   boolean  para   int  e retornar o código do erro que ocorreu. Isso é considerado uma má\n",
    "prática (conhecida também como uso de \"magic numbers\").\n",
    "Além de você perder o retorno do método, o valor devolvido é \"mágico\" e só legível perante extensa\n",
    "documentação, além de não obrigar o programador a tratar esse retorno e, no caso de esquecer isso, seu\n",
    "programa continuará rodando já num estado inconsistente.\n",
    "Por  esses  e  outro  motivos,  utilizamos  um  código  diferente  para  tratar  aquilo  que  chamamos  de\n",
    "exceções: os casos onde acontece algo que, normalmente, não iria acontecer. O exemplo do argumento\n",
    "do saque inválido ou do id inválido de um cliente é uma exceção à regra.\n",
    "Uma exceção representa uma situação que normalmente não ocorre e representa algo de estranho ou\n",
    "inesperado no sistema.\n",
    "Antes  de  resolvermos  o  nosso  problema,  vamos  ver  como  o  interpretador  age  ao  se  deparar  com\n",
    "situações inesperadas, como divisão por zero ou acesso a um índice de uma lista que não existe.\n",
    "Para  aprendermos  os  conceitos  básicos  das  exceptions  do  Python,  crie  um  arquivo  teste_erro.py  e\n",
    "teste o seguinte código você mesmo:"
   ]
  },
  {
   "cell_type": "code",
   "execution_count": 0,
   "metadata": {
    "colab": {},
    "colab_type": "code",
    "id": "x-zq7hQpqYF0"
   },
   "outputs": [],
   "source": [
    "def metodo1():\n",
    "    print('início do metodo1')\n",
    "    metodo2()\n",
    "    print('fim do metodo1')\n",
    "def metodo2():\n",
    "    print('início do metodo2')\n",
    "    cc = ContaCorrente('José', '123')\n",
    "    for i in range(1,15):\n",
    "        cc.deposita(i + 1000)\n",
    "        print(cc.saldo)\n",
    "        if(i == 5):\n",
    "            cc = None\n",
    "    print('fim do metodo2')\n",
    "if __name__ == '__main__':\n",
    "    print('início do main')\n",
    "    metodo1()\n",
    "    print('fim do main')"
   ]
  },
  {
   "cell_type": "markdown",
   "metadata": {
    "colab_type": "text",
    "id": "gvJ9WujXqbKu"
   },
   "source": [
    "Repare que durante a execução do programa chamamos o   metodo1()  e esse, por sua vez, chama o\n",
    " metodo2() . Cada um desses métodos pode ter suas próprias variáveis locais, isto é: o   metodo1()  não\n",
    "enxerga as variáveis declaradas dentro do executável e por aí em diante.\n",
    "Como o Python (e muitas outras linguagens) faz isso? Toda invocação de método é empilhado em\n",
    "uma estrutura de dados que isola a área e memória de cada um. Quando um método termina (retorna),\n",
    "ele  volta  para  o  método  que  o  invocou.  Ele  descobre  isso  através  da  pilha  de  execução  (stack):  basta\n",
    "remover o marcador que está no topo da pilha:\n",
    "Porém,  o  nosso   metodo2()   propositalmente  possui  um  enorme  problema:  está  acessando  uma\n",
    "referência para  None  quando o índice for igual a 6!\n",
    "Rode o código. Qual a saída? O que isso representa? O que ela indica?\n",
    "Essa saída é o rastro de pilha, o Traceback. É uma saída importantíssima para o programador - tanto\n",
    "que, em qualquer fórum ou lista de discussão, é comum os programadores enviarem, juntamente com a\n",
    "descrição do problema, essa Traceback. Mas por que isso aconteceu?\n",
    "O  sistema  de  exceções  do  Python  funciona  da  seguinte  maneira:  quando  uma  exceção  é  lançada\n",
    "(raise), o interpretador entra em estado de alerta e vai ver se o método atual toma alguma precaução ao\n",
    "tentar executar esse trecho de código. Como podemos ver, o   metodo2()  não toma nenhuma medida\n",
    "diferente do que vimos até agora.\n",
    "Como  o    metodo2()    não  está  tratando  esse  problema,  o  interpretador  para  a  execução  dele\n",
    "anormalmente,  sem  esperar  ele  terminar,  e  volta  um  stackframe  para  baixo,  onde  será  feita  nova\n",
    "verificação: \"o   método1()  está se precavendo de um problema chamado   AttributeError ?  \"Não...\"\n",
    "Volta para o executável, onde também não há proteção, então o interpretador morre.\n",
    "Obviamente, aqui estamos forçando esse caso e não faria sentido tomarmos cuidado com ele. É fácil\n",
    "arrumar  um  problema  desses:  basta  verificar  antes  de  chamar  os  métodos  se  a  variável  está  com\n",
    "referência para  None .\n",
    "Porém, apenas para entender o controle de fluxo de uma Exception, vamos colocar o código que vai\n",
    "tentar  (try)  executar  um  bloco  perigoso  e,  caso  o  problema  seja  do  tipo   AttributeError ,  ele  será\n",
    "excluído(except).  Repare  que  é  interessante  que  cada  exceção  no  Python  tenha  um  tipo...  ela  pode  ter\n",
    "atributos e métodos.\n",
    "Adicione um   try/except   em  volta  do   for ,  'pegando'  um   AttributeError .  O  que  o  código\n",
    "imprime?"
   ]
  },
  {
   "cell_type": "code",
   "execution_count": 0,
   "metadata": {
    "colab": {},
    "colab_type": "code",
    "id": "of2-fPiGqZbg"
   },
   "outputs": [],
   "source": [
    "from conta import ContaCorrente\n",
    "def metodo1():\n",
    "    print('início do metodo1')\n",
    "    metodo2()\n",
    "    print('fim do metodo1')\n",
    "def metodo2():\n",
    "    print('início do metodo2')\n",
    "    cc = ContaCorrente('José', '123')\n",
    "    try:\n",
    "        for i in range(1,15):\n",
    "            cc.deposita(i + 1000)\n",
    "            print(cc.saldo)\n",
    "            if(i == 5):\n",
    "            cc = None\n",
    "    except:\n",
    "        print('erro')\n",
    "    print('fim do metodo2')\n",
    "if __name__ == '__main__':\n",
    "    print('início do main')\n",
    "    metodo1()\n",
    "    print('fim do main')"
   ]
  },
  {
   "cell_type": "markdown",
   "metadata": {
    "colab_type": "text",
    "id": "BGi99kwMqndW"
   },
   "source": [
    "Em vez de fazer o  try  em torno do  for  inteiro, tente apenas com o bloco dentro do  for :"
   ]
  },
  {
   "cell_type": "code",
   "execution_count": 0,
   "metadata": {
    "colab": {},
    "colab_type": "code",
    "id": "FIiG_B_jqpfG"
   },
   "outputs": [],
   "source": [
    "def metodo2():\n",
    "    print('início do metodo2')\n",
    "    cc = ContaCorrente('José', '123')\n",
    "    for i in range(1,15):\n",
    "        try:\n",
    "            cc.deposita(i + 1000)\n",
    "            print(cc.saldo)\n",
    "            if(i == 5):\n",
    "                cc = None\n",
    "        except:\n",
    "            print('erro')\n",
    "    print('fim do metodo2')"
   ]
  },
  {
   "cell_type": "markdown",
   "metadata": {
    "colab_type": "text",
    "id": "OzgBcij_qscg"
   },
   "source": [
    "Qual a diferença?\n",
    "Retire o  try/except  e coloque ele em volta da chamada do  metodo2() :"
   ]
  },
  {
   "cell_type": "code",
   "execution_count": 0,
   "metadata": {
    "colab": {},
    "colab_type": "code",
    "id": "-wB2UqX4qt8z"
   },
   "outputs": [],
   "source": [
    "def metodo1():\n",
    "    print('início do metodo1')\n",
    "    try:\n",
    "        metodo2()\n",
    "    except AttributeError:\n",
    "        print('erro')   \n",
    "    print('fim do metodo1')"
   ]
  },
  {
   "cell_type": "markdown",
   "metadata": {
    "colab_type": "text",
    "id": "iDfdDhZyqxG_"
   },
   "source": [
    "Faça  o  mesmo,  retirando  o    try/except    novamente  e  colocando  em  volta  da  chamada  do\n",
    " metodo1() . Rode os códigos, o que acontece?"
   ]
  },
  {
   "cell_type": "code",
   "execution_count": 0,
   "metadata": {
    "colab": {},
    "colab_type": "code",
    "id": "V389BVgQqzIz"
   },
   "outputs": [],
   "source": [
    "if __name__ == '__main__':\n",
    "    print('início do main')\n",
    "    try:\n",
    "        metodo1()\n",
    "    except AttributeError:\n",
    "        print('erro')   \n",
    "    print('fim do main')"
   ]
  },
  {
   "cell_type": "markdown",
   "metadata": {
    "colab_type": "text",
    "id": "f8haMKz0q0og"
   },
   "source": [
    "Repare que, a partir do momento que uma exception foi catched (pega, tratada, handled), a exceção\n",
    "volta ao normal a partir daquele ponto."
   ]
  },
  {
   "cell_type": "markdown",
   "metadata": {
    "colab_type": "text",
    "id": "Ix7v3Pztq3H0"
   },
   "source": [
    "## 11.1 EXCEÇÕES E TIPOS DE ERROS\n",
    "\n",
    "### Runtime\n",
    "Este tipo de erro ocorre quando algo de errado acontece durante a execução do programa. A maior\n",
    "parte das mensagens deste tipo de erro inclui informações do que o programa estava fazendo e o local\n",
    "que o erro aconteceu.\n",
    "O interpretador mostra a famosa Traceback - ele mostra a sequência de chamadas de função que fez\n",
    "com  que  você  chegasse  onde  está,  incluindo  o  número  da  linha  de  seu  arquivo  onde  cada  chamada\n",
    "ocorreu.\n",
    "Os erros mais comuns de tempo de execução são:\n",
    "#### NameError\n",
    "Quando tentamos acessar uma variável que não existe.\n",
    "\n",
    "    print(x)\n",
    "    Traceback (most recent call last):\n",
    "    File \"<stdin>\", line 1, in <module>\n",
    "    NameError: name 'x' is not defined\n",
    "\n",
    "No exemplo acima tentamos imprimir  x  sem defini-lo antes. Este erro também é muito comum de\n",
    "ocorrer quando tentamos acessar um variável local em um contexto local.\n",
    "#### TypeError\n",
    "Quando  tentamos  usar  um  valor  de  forma  inadequada,  como  por  exemplo  tentar  indexar  um\n",
    "sequência com algo diferente de um número inteiro ou de um fatiamento:\n",
    "\n",
    "    lista = [1, 2, 3]\n",
    "    print(lista['a'])\n",
    "    Traceback (most recent call last):\n",
    "    File \"<stdin>\", line 2, in <module>\n",
    "    TypeError: list indices must be integers or slices, not str\n",
    "\n",
    "\n",
    "#### KeyError\n",
    "Quando tentamos acessar um elemento de um dicionário usando uma chave que não existe.\n",
    "\n",
    "    dicionario = {'nome': 'João', 'idade': 25}\n",
    "    print(dicionario['cidade'])\n",
    "    Traceback (most recent call last):\n",
    "    File \"<stdin>\", line 2, in <module>\n",
    "    KeyError: 'cidade'\n",
    "\n",
    "#### AttributeError\n",
    "Quando tentamos acessar um atributo ou método que não existe em um objeto.\n",
    "\n",
    "    lista = [1, 2, 3]\n",
    "    print(lista.nome)\n",
    "    Traceback (most recent call last):\n",
    "    File \"<stdin>\", line 2, in <module>\n",
    "    AttributeError: 'list' object has no attribute 'nome'\n",
    "\n",
    "#### IndexError\n",
    "Quando  tentamos  acessar  um  elemento  de  uma  sequência  com  um  índice  maior  que  seu\n",
    "comprimento menos um.\n",
    "\n",
    "    tupla = (1, 2, 3)\n",
    "    print(tupla[3])\n",
    "    Traceback (most recent call last):\n",
    "    File \"<stdin>\", line 2, in <module>\n",
    "    IndexError: tuple index out of range\n",
    "\n",
    "## 11.2 TRATANDO EXCEÇÕES\n",
    "Há  muitos  outros  erros  de  tempo  de  execução.  Que  tal  dividir  um  número  por  zero?  Será  que  o\n",
    "interpretador consegue fazer aquilo que \n",
    "nós definimos que não existe?\n",
    "\n",
    "    n = 2\n",
    "    n = n / 0\n",
    "    Traceback (most recent call last):\n",
    "    File \"<stdin>\", line 2, in <module>\n",
    "    ZeroDivisionError: division by zero\n",
    "\n",
    "Repare que um  ZeroDivisionError  poderia ser facilmente evitado com um   \n",
    "if  que checaria se o\n",
    "denominador  é  diferente  de  zero  mas  a  forma  correta  de  se  tratar  um  erro  no  Python  é  através  do\n",
    "comando try/except:\n",
    "\n",
    "    try:\n",
    "        n = n/0\n",
    "    except ZeroDivisionError:\n",
    "        print('divisão por zero')\n",
    "\n",
    "Que gera a saída:\n",
    "\n",
    "    divisão por zero\n",
    "\n",
    "O conjunto de instruções dentro do bloco   try  é executado (o interpretador tentará executar), se\n",
    "nenhuma  exceção  ocorrer,  o  comando   except   é  ignorado  e  a  execução  é  finalizada.  Mas  se  ocorrer\n",
    "alguma  exceção  durante  a  execução  do  bloco   try ,  as  instruções  remanescentes  são  ignoradas  e  se  a\n",
    "exceção lançada prever um  except , então as instruções dentro do bloco  except  são executadas.\n",
    "O comando  try  pode ter mais de um comando  except  para especificar múltiplos tratadores para\n",
    "diferentes exceções. No máximo um único tratador será ativado. Tratadores só são sensíveis às exceções\n",
    "levantadas  no  interior  da  cláusula   try ,  e  não  as  que  tenham  ocorrido  no  interior  de  outro  tratador\n",
    "numa  mesma  instrução    try  .  Um  tratador  pode  ser  sensível  a  múltiplas  exceções,  desde  que  as\n",
    "especifique em uma tupla:\n",
    "\n",
    "    except(RuntimeError, TypeError, NameError):\n",
    "        pass\n",
    "\n",
    "A última cláusula   except  pode omitir o nome da exceção, funcionando como um curinga. Não é\n",
    "aconselhável abusar deste recurso já que isso pode esconder erros do programador e do usuário.\n",
    "O bloco   try/except  possui um comando opcional   else  que, quando usado, deve ser colocado\n",
    "depois de todos os comandos  except . É útil para código que precisa ser executado se nenhuma exceção\n",
    "foi lançada, por exemplo:\n",
    "\n",
    "    try:\n",
    "        arquivo = open('palavras.txt', 'r')\n",
    "    except IOError:\n",
    "        print('não foi possível abrir o arquivo')\n",
    "    else:\n",
    "        print('o arquivo tem {} palavras'.format(len(arquivo.readlines())))\n",
    "        arquivo.close()"
   ]
  },
  {
   "cell_type": "markdown",
   "metadata": {
    "colab_type": "text",
    "id": "kRHVTDcftEg8"
   },
   "source": [
    "## 11.3 LEVANTANDO EXCEÇÕES\n",
    "O  comando   raise   nos  permite  forçar  a  ocorrência  de  um  determinado  tipo  de  exceção.  Por\n",
    "exemplo:\n",
    "\n",
    "    raise NameError('oi')\n",
    "    Traceback (most recent call last):\n",
    "    File \"<stdin>\", line 1, in ?\n",
    "    NameError: oi\n",
    "\n",
    "O argumento de   raise  indica a exceção a ser lançada. Esse argumento deve ser uma instância de\n",
    " Exception  ou uma classe de alguma exceção - uma classe que deriva de  Exception .\n",
    "Caso você precise determinar se uma exceção foi lançada ou não, mas não quer manipular o erro,\n",
    "uma forma é lançá-la novamente através da instrução  raise :\n",
    "\n",
    "    try:\n",
    "        raise NameError('oi')\n",
    "    except NameError:\n",
    "        print('lançou uma exceção')\n",
    "        raise\n",
    "\n",
    "Saída:\n",
    "\n",
    "    lançou uma exceção        \n",
    "    Traceback (most recent call last):\n",
    "    File \"<stdin>\", line 1, in ?\n",
    "    NameError: oi"
   ]
  },
  {
   "cell_type": "markdown",
   "metadata": {
    "colab_type": "text",
    "id": "FuxefMQktkFQ"
   },
   "source": [
    "## 11.4 DEFINIR UMA EXCEÇÃO\n",
    "Programas podem definir novos tipos de exceções, através da criação de uma nova classe. Exceções\n",
    "devem ser derivadas da classe  Exception , direta ou indiretamente. Por exemplo:\n",
    "\n",
    "    class MeuErro(Exception):\n",
    "        def __init__(self, valor):\n",
    "            self.valor = valor\n",
    "        def __str__(self):\n",
    "            return repr(self.valor)\n",
    "    if __name__ == '__main__':\n",
    "        try:\n",
    "            raise MeuErro(2*2)\n",
    "        except MeuErro as e:\n",
    "            print('Minha exceção ocorreu, valor: {}'.format(e.valor))\n",
    "        raise MeuErro('oops!')\n",
    "\n",
    "Que quando executado gera a saída:\n",
    "\n",
    "    Minha exceção ocorreu, valor: 4\n",
    "    Traceback (most recent call last):\n",
    "    File \"<stdin>\", line 13, in <module>\n",
    "        raise MeuErro('oops!')\n",
    "        __main__.MeuErro: 'oops!'\n",
    "\n",
    "Neste exemplo, o método   `__init__`  da classe   Exception  foi  reescrito. O  novo comportamento\n",
    "simplesmente  cria  o  atributo  valor.  Classes  de  exceções  podem  ser  definidas  para  fazer  qualquer  coisa\n",
    "que qualquer outra classe faz, mas em geral são bem simples, frequentemente oferecendo apenas alguns\n",
    "atributos que fornecem informações sobre o erro que ocorreu.\n",
    "Ao criar um módulo que pode gerar diversos erros, uma prática comum é criar uma classe base para\n",
    "as  exceções  definidas  por  aquele  módulo,  e  as  classes  específicas  para  cada  condição  de  erro  como\n",
    "subclasses dela:\n",
    "\n",
    "    class MeuError(Exception):\n",
    "        \"\"\"Classe base para outras exceções\"\"\"\n",
    "        pass\n",
    "    class ValorMuitoPequenoError(Error):\n",
    "        \"\"\"É lançada quando o valor passado é muito pequeno\"\"\"\n",
    "        pass\n",
    "    class ValorMuitoGrandeError(Error):\n",
    "        \"\"\"É lançada quando o valor passado é muito grande\"\"\"\n",
    "        pass\n",
    "\n",
    "Essa é a maneira padrão de definir exceções no Python mas o programador não precisa ficar preso a\n",
    "ela.  É  comum  que  novas  exceções  sejam  definidas  com  nomes  terminando  em  “Error”,  semelhante  a\n",
    "muitas exceções embutidas."
   ]
  },
  {
   "cell_type": "markdown",
   "metadata": {
    "colab_type": "text",
    "id": "e02PM6ebt4xi"
   },
   "source": [
    "## 11.5 PARA SABER MAIS: FINALLY\n",
    "O  comando  try  pode  ter  outro  comando  opcional  chamado  finally.  Sua  finalidade  é  permitir  a\n",
    "implementação  de  ações  de  limpeza,  que  sempre  devem  ser  executadas  independentemente  da\n",
    "ocorrência de exceções. Como no exemplo:\n",
    "\n",
    "    def divisao(x, y):\n",
    "        try:\n",
    "            resultado = x / y\n",
    "        except ZeroDivisionError:\n",
    "            print(\"Divisão por zero\")\n",
    "        else:\n",
    "            print(\"o resultado é {}\".format(resultado))\n",
    "        finally:\n",
    "            print(\"executando o finally\")\n",
    "    if __name__ == '__main__':\n",
    "        divide(2, 1)\n",
    "        divide(2, 0)\n",
    "        divide('2', '1')\n",
    "\n",
    "Executando:\n",
    "\n",
    "    resultado é 2\n",
    "    executando o finally\n",
    "    divisão por zero\n",
    "    executando o finally\n",
    "    executando o finally\n",
    "    Traceback (most recent call last):\n",
    "    File \"<stdin>\", line 1, in ?\n",
    "    File \"<stdin>\", line 3, in divide\n",
    "    TypeError: unsupported operand type(s) for /: 'str' and 'str'\n",
    "\n",
    "Repare  que  o  bloco  finally  é  executado  em  todos  os  casos.  A  exceção   TypeError   levantada  pela\n",
    "divisão de duas strings e não é tratada no except e portanto é relançada depois que o finally é executado.\n",
    "Em  aplicações  reais,  o  finally  é  útil  para  liberar  recursos  externos  (como  arquivos  ou  conexões  de\n",
    "rede), independentemente do uso do recurso ter sido bem sucedido ou não."
   ]
  },
  {
   "cell_type": "markdown",
   "metadata": {
    "colab_type": "text",
    "id": "Gb5d8Ds2uFoj"
   },
   "source": [
    "## 11.6 ÁRVORE DE EXCEÇÕES\n",
    "No  Python  todas  as  exceções  são  instâncias  de  uma  classe  derivada  de   BaseException .  Ela  não\n",
    "serve  para  ser  diretamente  herdada  por  exceções  criadas  por  programadores,  para  isso  utilizamos\n",
    " Exception  que também é filha de  BaseException .\n",
    "Abaixo está a hierarquia de classes de exceções do Python. Para mais informações sobre cada uma\n",
    "delas consulte a documentação: https://docs.python.org/3/library/exceptions.html\n",
    "\n",
    "    BaseException\n",
    "    +-- SystemExit\n",
    "    +-- KeyboardInterrupt\n",
    "    +-- GeneratorExit\n",
    "    +-- Exception\n",
    "        +-- StopIteration\n",
    "        +-- StopAsyncIteration\n",
    "        +-- ArithmeticError\n",
    "        |    +-- FloatingPointError\n",
    "        |    +-- OverflowError\n",
    "        |    +-- ZeroDivisionError\n",
    "        +-- AssertionError\n",
    "        +-- AttributeError\n",
    "        +-- BufferError\n",
    "        +-- EOFError\n",
    "        +-- ImportError\n",
    "        |    +-- ModuleNotFoundError\n",
    "        +-- LookupError\n",
    "        |    +-- IndexError\n",
    "        |    +-- KeyError\n",
    "        +-- MemoryError\n",
    "        +-- NameError\n",
    "        |    +-- UnboundLocalError\n",
    "        +-- OSError\n",
    "        |    +-- BlockingIOError\n",
    "        |    +-- ChildProcessError\n",
    "        |    +-- ConnectionError\n",
    "        |    |    +-- BrokenPipeError\n",
    "        |    |    +-- ConnectionAbortedError\n",
    "        |    |    +-- ConnectionRefusedError\n",
    "        |    |    +-- ConnectionResetError\n",
    "        |    +-- FileExistsError\n",
    "        |    +-- FileNotFoundError\n",
    "        |    +-- InterruptedError\n",
    "        |    +-- IsADirectoryError\n",
    "        |    +-- NotADirectoryError\n",
    "        |    +-- PermissionError\n",
    "        |    +-- ProcessLookupError\n",
    "        |    +-- TimeoutError\n",
    "        +-- ReferenceError\n",
    "        +-- RuntimeError\n",
    "        |    +-- NotImplementedError\n",
    "        |    +-- RecursionError\n",
    "        +-- SyntaxError\n",
    "        |    +-- IndentationError\n",
    "    \f",
    ".\n",
    "        |         +-- TabError\n",
    "        +-- SystemError\n",
    "        +-- TypeError\n",
    "        +-- ValueError\n",
    "        |    +-- UnicodeError\n",
    "        |         +-- UnicodeDecodeError\n",
    "        |         +-- UnicodeEncodeError\n",
    "        |         +-- UnicodeTranslateError\n",
    "        +-- Warning\n",
    "            +-- DeprecationWarning\n",
    "            +-- PendingDeprecationWarning\n",
    "            +-- RuntimeWarning\n",
    "            +-- SyntaxWarning\n",
    "            +-- UserWarning\n",
    "            +-- FutureWarning\n",
    "            +-- ImportWarning\n",
    "            +-- UnicodeWarning\n",
    "            +-- BytesWarning\n",
    "            +-- ResourceWarning"
   ]
  },
  {
   "cell_type": "markdown",
   "metadata": {
    "colab_type": "text",
    "id": "_oLcDxyXuOqp"
   },
   "source": [
    "### 11.7 EXERCÍCIOS: EXCEÇÕES\n",
    "1.  Na  classe   `Conta`,  modifique  o  método   `deposita()`.  Ele  deve  lançar  uma  exceção  chamada `ValueError`, que já  faz parte  da biblioteca padrão  do Python,  sempre que o  valor passado  como argumento for inválido (por exemplo, quando for negativo):\n",
    " \n",
    "        def deposita(self, valor):\n",
    "            if(valor < 0):\n",
    "                raise ValueError\n",
    "            else:\n",
    "                self._saldo += valor\n",
    "2.  Da  maneira  com  está,  apenas  saberemos  que  ocorreu  um   `ValueError`   mas  não  saberemos  o motivo. Vamos acrescentar uma mensagem para deixar o erro mais claro:\n",
    "\n",
    "        def deposita(self, valor):\n",
    "            if(valor < 0):\n",
    "                raise ValueError('Você tentou depositar um valor negativo')\n",
    "            else:\n",
    "                self._saldo += valor\n",
    "\n",
    "3.  Faça o mesmo para o método  `saca()`  da classe  `ContaCorrente`, afinal o cliente também não pode sacar um valor negativo.\n",
    "\n",
    "4.  Vamos validar também que o cliente não pode sacar um valor maior do que o saldo disponível em conta. Crie sua própria exceção chamada   `SaldoInsuficienteError`. Para isso, você precisa criar uma classe com esse nome que seja filha de `RuntimeError`.\n",
    "\n",
    "        class SaldoInsuficienteError(RuntimeError):\n",
    "            pass\n",
    "No método `saca()` da classe  `ContaCorrente`  vamos utilizar esta nova exceção:\n",
    "        class ContaCorrente(Conta):\n",
    "            # código omitido\n",
    "            def saca(self, valor):\n",
    "                if(valor < 0):\n",
    "                    raise ValueError('Você tentou sacar um valor negativo')\n",
    "                if(self._saldo < valor):\n",
    "                    raise SaldoInsuficienteError()\n",
    "                    self._saldo -= (valor + 0.10)\n"
   ]
  },
  {
   "cell_type": "markdown",
   "metadata": {
    "colab_type": "text",
    "id": "OBPMn6s1vjeY"
   },
   "source": [
    "### 11.8 OUTROS ERROS\n",
    "Erros  de  sintaxe  Um  dos  erros  mais  comuns  é  o  SyntaxError.  Geralmente  suas  mensagens  não dizem muito, a mais comum é a   \n",
    "\n",
    "    SyntaxError:  invalid  syntax\n",
    "\n",
    "Por outro  lado, a  mensagem diz  o  local  onde  o  problema  ocorreu.  -  onde  o  Python  encontrou  o  problema.  São  descobertos quando  o  interpretador  está  traduzindo  o  código  fonte  para  o  bytecode.  Indicam  que  há  algo  de\n",
    "errado com a estrutura do programa. Por exemplo: esquecer de fechar aspas, simples ou duplas, na hora  de  imprimir  um  mensagem;  esquecer  de  colocar  dois  pontos  (`:`)  ao  final  de  uma  instrução `if`, `while` ou `for` , etc...\n",
    "\n",
    "Erro  semântico (?) Este  erro  é  quando  o  programa  não  se  comporta  como  esperado.  \n",
    "\n",
    "Aqui  não  é lançada  uma  exceção,  o  programa  apenas  não  faz  a  coisa  certa.  São  mais  difíceis  de  encontrar porque o interpretador não fornece nenhuma informação já que não sabe o que o programa deveria fazer. São erros na regra de negócio. Utilizar a função  `print()`  em alguns lugares do código onde você suspeita que está gerando o erro pode ajudar."
   ]
  },
  {
   "cell_type": "markdown",
   "metadata": {
    "colab_type": "text",
    "id": "oU_lctuJvkad"
   },
   "source": [
    "### 11.9 PARA SABER MAIS - DEPURADOR DO PYTHON\n",
    "O depurador do Python, o `pdb`, é um módulo embutido que funciona como um console interativo\n",
    "onde é possível realizar debug de códigos python. Você pode ler mais a respeito na documentação:\n",
    "https://docs.python.org/3/library/pdb.html"
   ]
  }
 ],
 "metadata": {
  "colab": {
   "collapsed_sections": [
    "MUrJolt2-aD-",
    "3NqZ-0r1_q54",
    "RQ33gi3tDYEG",
    "nHDNPdbAFPh1",
    "ZhENGRztLHtI",
    "RCy0rjvJNXe4",
    "Uxbidv3xYPq7",
    "6yOIodPpbR6W",
    "ewCTTwW9c8iJ",
    "_louaPl3eq5r",
    "9eWtCzypfZGx",
    "t4nxmF1hjXsj",
    "r7BK-qFsktm5",
    "YEhH95O6iQ-J",
    "vN3yymMnkJJI",
    "-zT5izhklP47",
    "2oAom-dSljYS",
    "WjhzraVwmTWf",
    "2XyYPb_9mcUy",
    "U_oT0D5lK6g0",
    "PplhZST5N23M",
    "ascok5l4PHvW",
    "vjYownPjTGoh",
    "gVsP3_yGTqsA",
    "3CKu4tXrXbbs",
    "BKB4T2xOYQEP",
    "qx5zVH1MYP5A",
    "M2T54kleV5Tm",
    "L8S_l9K0gKlg",
    "DgKQHFOvh7a8",
    "sunWFmSkrWGV",
    "2lEfnXqks2Re",
    "tgIIPjRwt9rB",
    "O61Ni4k8uqbu",
    "uNqJNfQHwkzb",
    "AishUjoGzaYk",
    "6d6kpgatqA30",
    "Ix7v3Pztq3H0",
    "kRHVTDcftEg8",
    "FuxefMQktkFQ",
    "e02PM6ebt4xi",
    "Gb5d8Ds2uFoj",
    "_oLcDxyXuOqp",
    "OBPMn6s1vjeY",
    "oU_lctuJvkad",
    "SexMNv3YxHRI",
    "4ydBnFxPx93t",
    "dD_ll8EozLcD",
    "Y2jIpz8XznFX",
    "0NTEep5Vz2iw",
    "n5XXGyWO0Ggp",
    "-WadxXBc1dqs",
    "YG_NggJf3hcF",
    "FNXtNVIC4Ux4",
    "lhXWleU44qsk",
    "WMs0GsRZ81An",
    "_CuEWMIHAtBX",
    "QUtt8tjrBE-J",
    "vbrd9w31BeTB",
    "qUp89EGuBeII",
    "apu1fbOYB5Sy",
    "DGRgurSOCM9S",
    "Dq1idRRXCh3J"
   ],
   "name": "Parte_2.ipynb",
   "provenance": []
  },
  "kernelspec": {
   "display_name": "Python 3",
   "language": "python",
   "name": "python3"
  },
  "language_info": {
   "codemirror_mode": {
    "name": "ipython",
    "version": 3
   },
   "file_extension": ".py",
   "mimetype": "text/x-python",
   "name": "python",
   "nbconvert_exporter": "python",
   "pygments_lexer": "ipython3",
   "version": "3.7.6"
  }
 },
 "nbformat": 4,
 "nbformat_minor": 1
}
